Workbook

Sheet Regression_Dashboard
A1: Moodle Regression Testing - Dashboard
A2: QA updates Case_Status (Pass/Fail/Blocked) on each module sheet as cases are executed. Executed = automated cases run (Pass/Fail/Blocked). Not Automatable = Automated=No. Not Executed = Total - Executed - Not Automatable. Completion % = Executed / (Total - Not Automatable). Assessment_Activity_Creation = assessment_create.feature TC-1..TC-47 (47). Assessment_User_Functionality = assessment_user_functionality.feature @A-user-1..24 (24).
A4: S.No | B4: Feature Module | C4: Total Test Cases | D4: QA Assigned | E4: Executed | F4: Not Automatable | G4: Deferred | H4: Completion %
A5: 1 | B5: Moodle_users | C5: 49 | E5: 32 | F5: 17 | G5: 0 | H5: 1
A6: 2 | B6: Upload_Users | C6: 48 | E6: 43 | F6: 5 | G6: 0 | H6: 1
A7: 3 | B7: All Course Page | C7: 110 | E7: 95 | F7: 15 | G7: 0 | H7: 1
A8: 4 | B8: Moodle_Sandbox_Labs | C8: 62 | E8: 53 | F8: 9 | G8: 0 | H8: 1
A9: 5 | B9: Assessment (Activity Creation + User Functionality) | C9: 372 | E9: 71 | F9: 0 | G9: 301 | H9: 0.19086022
A10: 6 | B10: Practice_Project | C10: 210 | E10: 114 | F10: 79 | G10: 17 | H10: 0.87022901
A11: 7 | B11: Moodle_Lab_Templates | C11: 84 | E11: 66 | F11: 18 | G11: 0 | H11: 1
A12: 8 | B12: Moodle settings | C12: 79 | E12: 79 | F12: 0 | G12: 0 | H12: 1
A13: 9 | B13: Moodle-Cloudlabs Integration | C13: 13 | E13: 11 | F13: 2 | G13: 0 | H13: 1
A14: 10 | B14: Sequential_Activity_Completion | C14: 28 | E14: 28 | F14: 0 | G14: 0 | H14: 1
A15: 11 | B15: Difficulty_Level_Configuration | C15: 16 | E15: 16 | F15: 0 | G15: 0 | H15: 1
A16: 12 | B16: Content_Integration_Git_URL | C16: 26 | E16: 9 | F16: 15 | G16: 2 | H16: 0.81818182
... A18: 14 | B18: Pre_Delivery_Lab_Checklist | C18: 76 | E18: 71 | F18: 5 | G18: 0 | H18: 1
B19: TOTAL | C19: 1217 | E19: 711 | F19: 186 | G19: 320 | H19: 0.68962173

Sheet Release_Regression_Plan
A1: Release Regression Plan - Smart Coverage (Smoke + Core, scoped per release)
A2: How to use this sheet for every release (not weekly - re-check this each time a new release's feature files are merged in):
A3: 1) Set 'Impacted This Release?' to Yes for every module this release's feature files touched (new sheets, or sheets that got new/changed rows). Leave No for untouched modules.
A4: 2) Assign a 'QA Assigned' owner per module so the release regression workload is split across the team by module.
A5: 3) Smoke tier cases run EVERY release regardless of impact (core happy-path safety net). Core tier only runs for Impacted modules. Extended tier is NOT part of the release plan - run it separately as a periodic full sweep (monthly/quarterly).
A6: 4) 'This Release's Planned Cases' and 'Planned Completion %' update automatically from the Regression_Tier and Case_Status columns (col J and col G) in each module sheet as QA executes.
A7: 5) Each test case sheet has a Regression_Tier column (Smoke / Core / Extended) - orange=Smoke, blue=Core, green=Extended. Priority (col F) has also been reviewed: Critical/High/Medium/Low.
A9: S.No | B9: Feature Module | C9: Total Cases | D9: Smoke | E9: Core | F9: Extended | G9: Impacted This Release? | H9: QA Assigned | I9: This Release's Planned Cases | J9: Planned Executed | K9: Automated | L9: Planned Completion % | M9: Automated
A10: 1 | B10: Moodle_users | C10: =COUNTA('Moodle_users'!B2:B2000) -> 49 | D10: =COUNTIF('Moodle_users'!J2:J2000,"Smoke") -> 5 | E10: =COUNTIF('Moodle_users'!J2:J2000,"Core") -> 24 | F10: =COUNTIF('Moodle_users'!J2:J2000,"Extended") -> 6 | I10: =D10+IF(G10="Yes",E10,0) -> 5 | J10: =SUMPRODUCT(('Moodle_users'!J2:J2000="Smoke")*((LOWER('Moodle_users'!G2:G2000)="pass")+(LOWER('Moodle_users'!G2:G2000)="fail")+(LOWER('Moodle_users'!G2:G2000)="failed")+(LOWER('Moodle_users'!G2:G2000)="blocked")+(LOWER('Moodle_users'!G2:G2000)="na")+(LOWER('Moodle_users'!G2:G2000)="n/a")+(LOWER('Moodle_users'!G2:G2000)="not applicable")))+IF(G10="Yes",SUMPRODUCT(('Moodle_users'!J2:J2000="Core")*((LOWER('Moodle_users'!G2:G2000)="pass")+(LOWER('Moodle_users'!G2:G2000)="fail")+(LOWER('Moodle_users'!G2:G2000)="failed")+(LOWER('Moodle_users'!G2:G2000)="blocked")+(LOWER('Moodle_users'!G2:G2000)="na")+(LOWER('Moodle_users'!G2:G2000)="n/a")+(LOWER('Moodle_users'!G2:G2000)="not applicable"))),0) -> 5 | K10: Yes | L10: =IF(I10=0,0,J10/I10) -> 1
A11: 2 | B11: Upload_Users | C11: =COUNTA('Upload_Users'!B2:B2000) -> 48 | D11: =COUNTIF('Upload_Users'!J2:J2000,"Smoke") -> 0 | E11: =COUNTIF('Upload_Users'!J2:J2000,"Core") -> 20 | F11: =COUNTIF('Upload_Users'!J2:J2000,"Extended") -> 28 | I11: =D11+IF(G11="Yes",E11,0) -> 0 | J11: =SUMPRODUCT(('Upload_Users'!J2:J2000="Smoke")*((LOWER('Upload_Users'!G2:G2000)="pass")+(LOWER('Upload_Users'!G2:G2000)="fail")+(LOWER('Upload_Users'!G2:G2000)="failed")+(LOWER('Upload_Users'!G2:G2000)="blocked")+(LOWER('Upload_Users'!G2:G2000)="na")+(LOWER('Upload_Users'!G2:G2000)="n/a")+(LOWER('Upload_Users'!G2:G2000)="not applicable")))+IF(G11="Yes",SUMPRODUCT(('Upload_Users'!J2:J2000="Core")*((LOWER('Upload_Users'!G2:G2000)="pass")+(LOWER('Upload_Users'!G2:G2000)="fail")+(LOWER('Upload_Users'!G2:G2000)="failed")+(LOWER('Upload_Users'!G2:G2000)="blocked")+(LOWER('Upload_Users'!G2:G2000)="na")+(LOWER('Upload_Users'!G2:G2000)="n/a")+(LOWER('Upload_Users'!G2:G2000)="not applicable"))),0) -> 0 | K11: Yes | L11: =IF(I11=0,0,J11/I11) -> 0
A12: 3 | B12: All Course Page | C12: =COUNTA('All Course Page '!B2:B2000) -> 110 | D12: =COUNTIF('All Course Page '!J2:J2000,"Smoke") -> 2 | E12: =COUNTIF('All Course Page '!J2:J2000,"Core") -> 89 | F12: =COUNTIF('All Course Page '!J2:J2000,"Extended") -> 19 | I12: =D12+IF(G12="Yes",E12,0) -> 2 | J12: =SUMPRODUCT(('All Course Page '!J2:J2000="Smoke")*((LOWER('All Course Page '!G2:G2000)="pass")+(LOWER('All Course Page '!G2:G2000)="fail")+(LOWER('All Course Page '!G2:G2000)="failed")+(LOWER('All Course Page '!G2:G2000)="blocked")+(LOWER('All Course Page '!G2:G2000)="na")+(LOWER('All Course Page '!G2:G2000)="n/a")+(LOWER('All Course Page '!G2:G2000)="not applicable")))+IF(G12="Yes",SUMPRODUCT(('All Course Page '!J2:J2000="Core")*((LOWER('All Course Page '!G2:G2000)="pass")+(LOWER('All Course Page '!G2:G2000)="fail")+(LOWER('All Course Page '!G2:G2000)="failed")+(LOWER('All Course Page '!G2:G2000)="blocked")+(LOWER('All Course Page '!G2:G2000)="na")+(LOWER('All Course Page '!G2:G2000)="n/a")+(LOWER('All Course Page '!G2:G2000)="not applicable"))),0) -> 2 | K12: Yes | L12: =IF(I12=0,0,J12/I12) -> 1
A13: 4 | B13: Moodle_Sandbox_Labs | C13: =COUNTA('Moodle_Sandbox_Labs'!B2:B2000) -> 62 | D13: =COUNTIF('Moodle_Sandbox_Labs'!J2:J2000,"Smoke") -> 1 | E13: =COUNTIF('Moodle_Sandbox_Labs'!J2:J2000,"Core") -> 20 | F13: =COUNTIF('Moodle_Sandbox_Labs'!J2:J2000,"Extended") -> 5 | I13: =D13+IF(G13="Yes",E13,0) -> 1 | J13: =SUMPRODUCT(('Moodle_Sandbox_Labs'!J2:J2000="Smoke")*((LOWER('Moodle_Sandbox_Labs'!G2:G2000)="pass")+(LOWER('Moodle_Sandbox_Labs'!G2:G2000)="fail")+(LOWER('Moodle_Sandbox_Labs'!G2:G2000)="failed")+(LOWER('Moodle_Sandbox_Labs'!G2:G2000)="blocked")+(LOWER('Moodle_Sandbox_Labs'!G2:G2000)="na")+(LOWER('Moodle_Sandbox_Labs'!G2:G2000)="n/a")+(LOWER('Moodle_Sandbox_Labs'!G2:G2000)="not applicable")))+IF(G13="Yes",SUMPRODUCT(('Moodle_Sandbox_Labs'!J2:J2000="Core")*((LOWER('Moodle_Sandbox_Labs'!G2:G2000)="pass")+(LOWER('Moodle_Sandbox_Labs'!G2:G2000)="fail")+(LOWER('Moodle_Sandbox_Labs'!G2:G2000)="failed")+(LOWER('Moodle_Sandbox_Labs'!G2:G2000)="blocked")+(LOWER('Moodle_Sandbox_Labs'!G2:G2000)="na")+(LOWER('Moodle_Sandbox_Labs'!G2:G2000)="n/a")+(LOWER('Moodle_Sandbox_Labs'!G2:G2000)="not applicable"))),0) -> 1 | K13: Yes | L13: =IF(I13=0,0,J13/I13) -> 1
A14: 5 | B14: Moodle_Assessment_Labs | C14: =COUNTA('Moodle_Assessment_Labs'!B2:B2000) -> 372 | D14: =COUNTIF('Moodle_Assessment_Labs'!J2:J2000,"Smoke") -> 12 | E14: =COUNTIF('Moodle_Assessment_Labs'!J2:J2000,"Core") -> 338 | F14: =COUNTIF('Moodle_Assessment_Labs'!J2:J2000,"Extended") -> 11 | I14: =D14+IF(G14="Yes",E14,0) -> 12 | J14: =SUMPRODUCT(('Moodle_Assessment_Labs'!J2:J2000="Smoke")*((LOWER('Moodle_Assessment_Labs'!G2:G2000)="pass")+(LOWER('Moodle_Assessment_Labs'!G2:G2000)="fail")+(LOWER('Moodle_Assessment_Labs'!G2:G2000)="failed")+(LOWER('Moodle_Assessment_Labs'!G2:G2000)="blocked")+(LOWER('Moodle_Assessment_Labs'!G2:G2000)="na")+(LOWER('Moodle_Assessment_Labs'!G2:G2000)="n/a")+(LOWER('Moodle_Assessment_Labs'!G2:G2000)="not applicable")))+IF(G14="Yes",SUMPRODUCT(('Moodle_Assessment_Labs'!J2:J2000="Core")*((LOWER('Moodle_Assessment_Labs'!G2:G2000)="pass")+(LOWER('Moodle_Assessment_Labs'!G2:G2000)="fail")+(LOWER('Moodle_Assessment_Labs'!G2:G2000)="failed")+(LOWER('Moodle_Assessment_Labs'!G2:G2000)="blocked")+(LOWER('Moodle_Assessment_Labs'!G2:G2000)="na")+(LOWER('Moodle_Assessment_Labs'!G2:G2000)="n/a")+(LOWER('Moodle_Assessment_Labs'!G2:G2000)="not applicable"))),0) -> 4 | K14: Inprogress | L14: =IF(I14=0,0,J14/I14) -> 0.33333333
A15: 6 | B15: Practice_Project | C15: =COUNTA('Practice_Project'!B2:B2000) -> 210 | D15: =COUNTIF('Practice_Project'!J2:J2000,"Smoke") -> 16 | E15: =COUNTIF('Practice_Project'!J2:J2000,"Core") -> 172 | F15: =COUNTIF('Practice_Project'!J2:J2000,"Extended") -> 10 | I15: =D15+IF(G15="Yes",E15,0) -> 16 | J15: =SUMPRODUCT(('Practice_Project'!J2:J2000="Smoke")*((LOWER('Practice_Project'!G2:G2000)="pass")+(LOWER('Practice_Project'!G2:G2000)="fail")+(LOWER('Practice_Project'!G2:G2000)="failed")+(LOWER('Practice_Project'!G2:G2000)="blocked")+(LOWER('Practice_Project'!G2:G2000)="na")+(LOWER('Practice_Project'!G2:G2000)="n/a")+(LOWER('Practice_Project'!G2:G2000)="not applicable")))+IF(G15="Yes",SUMPRODUCT(('Practice_Project'!J2:J2000="Core")*((LOWER('Practice_Project'!G2:G2000)="pass")+(LOWER('Practice_Project'!G2:G2000)="fail")+(LOWER('Practice_Project'!G2:G2000)="failed")+(LOWER('Practice_Project'!G2:G2000)="blocked")+(LOWER('Practice_Project'!G2:G2000)="na")+(LOWER('Practice_Project'!G2:G2000)="n/a")+(LOWER('Practice_Project'!G2:G2000)="not applicable"))),0) -> 16 | K15: NS | L15: =IF(I15=0,0,J15/I15) -> 1
A16: 7 | B16: Moodle_Lab_Templates | C16: =COUNTA('Moodle_Lab_Templates'!B2:B2000) -> 84 | D16: =COUNTIF('Moodle_Lab_Templates'!J2:J2000,"Smoke") -> 5 | E16: =COUNTIF('Moodle_Lab_Templates'!J2:J2000,"Core") -> 69 | F16: =COUNTIF('Moodle_Lab_Templates'!J2:J2000,"Extended") -> 6 | I16: =D16+IF(G16="Yes",E16,0) -> 5 | J16: =SUMPRODUCT(('Moodle_Lab_Templates'!J2:J2000="Smoke")*((LOWER('Moodle_Lab_Templates'!G2:G2000)="pass")+(LOWER('Moodle_Lab_Templates'!G2:G2000)="fail")+(LOWER('Moodle_Lab_Templates'!G2:G2000)="failed")+(LOWER('Moodle_Lab_Templates'!G2:G2000)="blocked")+(LOWER('Moodle_Lab_Templates'!G2:G2000)="na")+(LOWER('Moodle_Lab_Templates'!G2:G2000)="n/a")+(LOWER('Moodle_Lab_Templates'!G2:G2000)="not applicable")))+IF(G16="Yes",SUMPRODUCT(('Moodle_Lab_Templates'!J2:J2000="Core")*((LOWER('Moodle_Lab_Templates'!G2:G2000)="pass")+(LOWER('Moodle_Lab_Templates'!G2:G2000)="fail")+(LOWER('Moodle_Lab_Templates'!G2:G2000)="failed")+(LOWER('Moodle_Lab_Templates'!G2:G2000)="blocked")+(LOWER('Moodle_Lab_Templates'!G2:G2000)="na")+(LOWER('Moodle_Lab_Templates'!G2:G2000)="n/a")+(LOWER('Moodle_Lab_Templates'!G2:G2000)="not applicable"))),0) -> 5 | K16: Inprogress | L16: =IF(I16=0,0,J16/I16) -> 1
A17: 8 | B17: Groups_Testcases | C17: =COUNTA('Groups_Testcases'!B2:B2000) -> 59 | D17: =COUNTIF('Groups_Testcases'!J2:J2000,"Smoke") -> 3 | E17: =COUNTIF('Groups_Testcases'!J2:J2000,"Core") -> 43 | F17: =COUNTIF('Groups_Testcases'!J2:J2000,"Extended") -> 2 | I17: =D17+IF(G17="Yes",E17,0) -> 3 | J17: =SUMPRODUCT(('Groups_Testcases'!J2:J2000="Smoke")*((LOWER('Groups_Testcases'!G2:G2000)="pass")+(LOWER('Groups_Testcases'!G2:G2000)="fail")+(LOWER('Groups_Testcases'!G2:G2000)="failed")+(LOWER('Groups_Testcases'!G2:G2000)="blocked")+(LOWER('Groups_Testcases'!G2:G2000)="na")+(LOWER('Groups_Testcases'!G2:G2000)="n/a")+(LOWER('Groups_Testcases'!G2:G2000)="not applicable")))+IF(G17="Yes",SUMPRODUCT(('Groups_Testcases'!J2:J2000="Core")*((LOWER('Groups_Testcases'!G2:G2000)="pass")+(LOWER('Groups_Testcases'!G2:G2000)="fail")+(LOWER('Groups_Testcases'!G2:G2000)="failed")+(LOWER('Groups_Testcases'!G2:G2000)="blocked")+(LOWER('Groups_Testcases'!G2:G2000)="na")+(LOWER('Groups_Testcases'!G2:G2000)="n/a")+(LOWER('Groups_Testcases'!G2:G2000)="not applicable"))),0) -> 3 | K17: NS | L17: =IF(I17=0,0,J17/I17) -> 1
A18: 9 | B18: Moodle_Roles | C18: =COUNTA('Moodle_Roles'!B2:B2000) -> 99 | D18: =COUNTIF('Moodle_Roles'!J2:J2000,"Smoke") -> 12 | E18: =COUNTIF('Moodle_Roles'!J2:J2000,"Core") -> 76 | F18: =COUNTIF('Moodle_Roles'!J2:J2000,"Extended") -> 2 | I18: =D18+IF(G18="Yes",E18,0) -> 12 | J18: =SUMPRODUCT(('Moodle_Roles'!J2:J2000="Smoke")*((LOWER('Moodle_Roles'!G2:G2000)="pass")+(LOWER('Moodle_Roles'!G2:G2000)="fail")+(LOWER('Moodle_Roles'!G2:G2000)="failed")+(LOWER('Moodle_Roles'!G2:G2000)="blocked")+(LOWER('Moodle_Roles'!G2:G2000)="na")+(LOWER('Moodle_Roles'!G2:G2000)="n/a")+(LOWER('Moodle_Roles'!G2:G2000)="not applicable")))+IF(G18="Yes",SUMPRODUCT(('Moodle_Roles'!J2:J2000="Core")*((LOWER('Moodle_Roles'!G2:G2000)="pass")+(LOWER('Moodle_Roles'!G2:G2000)="fail")+(LOWER('Moodle_Roles'!G2:G2000)="failed")+(LOWER('Moodle_Roles'!G2:G2000)="blocked")+(LOWER('Moodle_Roles'!G2:G2000)="na")+(LOWER('Moodle_Roles'!G2:G2000)="n/a")+(LOWER('Moodle_Roles'!G2:G2000)="not applicable"))),0) -> 4 | K18: NS | L18: =IF(I18=0,0,J18/I18) -> 0.33333333
A19: 10 | B19: Moodle_Tags | C19: =COUNTA('Moodle_Tags'!B2:B2000) -> 54 | D19: =COUNTIF('Moodle_Tags'!J2:J2000,"Smoke") -> 0 | E19: =COUNTIF('Moodle_Tags'!J2:J2000,"Core") -> 32 | F19: =COUNTIF('Moodle_Tags'!J2:J2000,"Extended") -> 11 | I19: =D19+IF(G19="Yes",E19,0) -> 0 | J19: =SUMPRODUCT(('Moodle_Tags'!J2:J2000="Smoke")*((LOWER('Moodle_Tags'!G2:G2000)="pass")+(LOWER('Moodle_Tags'!G2:G2000)="fail")+(LOWER('Moodle_Tags'!G2:G2000)="failed")+(LOWER('Moodle_Tags'!G2:G2000)="blocked")+(LOWER('Moodle_Tags'!G2:G2000)="na")+(LOWER('Moodle_Tags'!G2:G2000)="n/a")+(LOWER('Moodle_Tags'!G2:G2000)="not applicable")))+IF(G19="Yes",SUMPRODUCT(('Moodle_Tags'!J2:J2000="Core")*((LOWER('Moodle_Tags'!G2:G2000)="pass")+(LOWER('Moodle_Tags'!G2:G2000)="fail")+(LOWER('Moodle_Tags'!G2:G2000)="failed")+(LOWER('Moodle_Tags'!G2:G2000)="blocked")+(LOWER('Moodle_Tags'!G2:G2000)="na")+(LOWER('Moodle_Tags'!G2:G2000)="n/a")+(LOWER('Moodle_Tags'!G2:G2000)="not applicable"))),0) -> 0 | K19: NS | L19: =IF(I19=0,0,J19/I19) -> 0
A20: 11 | B20: Moodle_Logs | C20: =COUNTA('Moodle_Logs'!B2:B2000) -> 50 | D20: =COUNTIF('Moodle_Logs'!J2:J2000,"Smoke") -> 6 | E20: =COUNTIF('Moodle_Logs'!J2:J2000,"Core") -> 42 | F20: =COUNTIF('Moodle_Logs'!J2:J2000,"Extended") -> 2 | I20: =D20+IF(G20="Yes",E20,0) -> 6 | J20: =SUMPRODUCT(('Moodle_Logs'!J2:J2000="Smoke")*((LOWER('Moodle_Logs'!G2:G2000)="pass")+(LOWER('Moodle_Logs'!G2:G2000)="fail")+(LOWER('Moodle_Logs'!G2:G2000)="failed")+(LOWER('Moodle_Logs'!G2:G2000)="blocked")+(LOWER('Moodle_Logs'!G2:G2000)="na")+(LOWER('Moodle_Logs'!G2:G2000)="n/a")+(LOWER('Moodle_Logs'!G2:G2000)="not applicable")))+IF(G20="Yes",SUMPRODUCT(('Moodle_Logs'!J2:J2000="Core")*((LOWER('Moodle_Logs'!G2:G2000)="pass")+(LOWER('Moodle_Logs'!G2:G2000)="fail")+(LOWER('Moodle_Logs'!G2:G2000)="failed")+(LOWER('Moodle_Logs'!G2:G2000)="blocked")+(LOWER('Moodle_Logs'!G2:G2000)="na")+(LOWER('Moodle_Logs'!G2:G2000)="n/a")+(LOWER('Moodle_Logs'!G2:G2000)="not applicable"))),0) -> 4 | K20: NS | L20: =IF(I20=0,0,J20/I20) -> 0.66666667
A21: 12 | B21: LoadBalacer_Moodle | C21: =COUNTA('LoadBalacer_Moodle'!B2:B2000) -> 7 | D21: =COUNTIF('LoadBalacer_Moodle'!J2:J2000,"Smoke") -> 0 | E21: =COUNTIF('LoadBalacer_Moodle'!J2:J2000,"Core") -> 5 | F21: =COUNTIF('LoadBalacer_Moodle'!J2:J2000,"Extended") -> 2 | I21: =D21+IF(G21="Yes",E21,0) -> 0 | J21: =SUMPRODUCT(('LoadBalacer_Moodle'!J2:J2000="Smoke")*((LOWER('LoadBalacer_Moodle'!G2:G2000)="pass")+(LOWER('LoadBalacer_Moodle'!G2:G2000)="fail")+(LOWER('LoadBalacer_Moodle'!G2:G2000)="failed")+(LOWER('LoadBalacer_Moodle'!G2:G2000)="blocked")+(LOWER('LoadBalacer_Moodle'!G2:G2000)="na")+(LOWER('LoadBalacer_Moodle'!G2:G2000)="n/a")+(LOWER('LoadBalacer_Moodle'!G2:G2000)="not applicable")))+IF(G21="Yes",SUMPRODUCT(('LoadBalacer_Moodle'!J2:J2000="Core")*((LOWER('LoadBalacer_Moodle'!G2:G2000)="pass")+(LOWER('LoadBalacer_Moodle'!G2:G2000)="fail")+(LOWER('LoadBalacer_Moodle'!G2:G2000)="failed")+(LOWER('LoadBalacer_Moodle'!G2:G2000)="blocked")+(LOWER('LoadBalacer_Moodle'!G2:G2000)="na")+(LOWER('LoadBalacer_Moodle'!G2:G2000)="n/a")+(LOWER('LoadBalacer_Moodle'!G2:G2000)="not applicable"))),0) -> 0 | K21: NS | L21: =IF(I21=0,0,J21/I21) -> 0
A22: 13 | B22: Moodle_Reports | C22: =COUNTA('Moodle_Reports'!B2:B2000) -> 205 | D22: =COUNTIF('Moodle_Reports'!J2:J2000,"Smoke") -> 3 | E22: =COUNTIF('Moodle_Reports'!J2:J2000,"Core") -> 114 | F22: =COUNTIF('Moodle_Reports'!J2:J2000,"Extended") -> 85 | I22: =D22+IF(G22="Yes",E22,0) -> 3 | J22: =SUMPRODUCT(('Moodle_Reports'!J2:J2000="Smoke")*((LOWER('Moodle_Reports'!G2:G2000)="pass")+(LOWER('Moodle_Reports'!G2:G2000)="fail")+(LOWER('Moodle_Reports'!G2:G2000)="failed")+(LOWER('Moodle_Reports'!G2:G2000)="blocked")+(LOWER('Moodle_Reports'!G2:G2000)="na")+(LOWER('Moodle_Reports'!G2:G2000)="n/a")+(LOWER('Moodle_Reports'!G2:G2000)="not applicable")))+IF(G22="Yes",SUMPRODUCT(('Moodle_Reports'!J2:J2000="Core")*((LOWER('Moodle_Reports'!G2:G2000)="pass")+(LOWER('Moodle_Reports'!G2:G2000)="fail")+(LOWER('Moodle_Reports'!G2:G2000)="failed")+(LOWER('Moodle_Reports'!G2:G2000)="blocked")+(LOWER('Moodle_Reports'!G2:G2000)="na")+(LOWER('Moodle_Reports'!G2:G2000)="n/a")+(LOWER('Moodle_Reports'!G2:G2000)="not applicable"))),0) -> 2 | K22: NS | L22: =IF(I22=0,0,J22/I22) -> 0.66666667
A23: 14 | B23: Moodle_cron | C23: =COUNTA('Moodle_cron'!B2:B2000) -> 17 | D23: =COUNTIF('Moodle_cron'!J2:J2000,"Smoke") -> 3 | E23: =COUNTIF('Moodle_cron'!J2:J2000,"Core") -> 1 | F23: =COUNTIF('Moodle_cron'!J2:J2000,"Extended") -> 13 | I23: =D23+IF(G23="Yes",E23,0) -> 3 | J23: =SUMPRODUCT(('Moodle_cron'!J2:J2000="Smoke")*((LOWER('Moodle_cron'!G2:G2000)="pass")+(LOWER('Moodle_cron'!G2:G2000)="fail")+(LOWER('Moodle_cron'!G2:G2000)="failed")+(LOWER('Moodle_cron'!G2:G2000)="blocked")+(LOWER('Moodle_cron'!G2:G2000)="na")+(LOWER('Moodle_cron'!G2:G2000)="n/a")+(LOWER('Moodle_cron'!G2:G2000)="not applicable")))+IF(G23="Yes",SUMPRODUCT(('Moodle_cron'!J2:J2000="Core")*((LOWER('Moodle_cron'!G2:G2000)="pass")+(LOWER('Moodle_cron'!G2:G2000)="fail")+(LOWER('Moodle_cron'!G2:G2000)="failed")+(LOWER('Moodle_cron'!G2:G2000)="blocked")+(LOWER('Moodle_cron'!G2:G2000)="na")+(LOWER('Moodle_cron'!G2:G2000)="n/a")+(LOWER('Moodle_cron'!G2:G2000)="not applicable"))),0) -> 0 | K23: NS | L23: =IF(I23=0,0,J23/I23) -> 0
A24: 15 | B24: Moodle-Cloudlabs Integration | C24: =COUNTA('Moodle-Cloudlabs Integration'!B2:B2000) -> 13 | D24: =COUNTIF('Moodle-Cloudlabs Integration'!J2:J2000,"Smoke") -> 0 | E24: =COUNTIF('Moodle-Cloudlabs Integration'!J2:J2000,"Core") -> 11 | F24: =COUNTIF('Moodle-Cloudlabs Integration'!J2:J2000,"Extended") -> 2 | I24: =D24+IF(G24="Yes",E24,0) -> 0 | J24: =SUMPRODUCT(('Moodle-Cloudlabs Integration'!J2:J2000="Smoke")*((LOWER('Moodle-Cloudlabs Integration'!G2:G2000)="pass")+(LOWER('Moodle-Cloudlabs Integration'!G2:G2000)="fail")+(LOWER('Moodle-Cloudlabs Integration'!G2:G2000)="failed")+(LOWER('Moodle-Cloudlabs Integration'!G2:G2000)="blocked")+(LOWER('Moodle-Cloudlabs Integration'!G2:G2000)="na")+(LOWER('Moodle-Cloudlabs Integration'!G2:G2000)="n/a")+(LOWER('Moodle-Cloudlabs Integration'!G2:G2000)="not applicable")))+IF(G24="Yes",SUMPRODUCT(('Moodle-Cloudlabs Integration'!J2:J2000="Core")*((LOWER('Moodle-Cloudlabs Integration'!G2:G2000)="pass")+(LOWER('Moodle-Cloudlabs Integration'!G2:G2000)="fail")+(LOWER('Moodle-Cloudlabs Integration'!G2:G2000)="failed")+(LOWER('Moodle-Cloudlabs Integration'!G2:G2000)="blocked")+(LOWER('Moodle-Cloudlabs Integration'!G2:G2000)="na")+(LOWER('Moodle-Cloudlabs Integration'!G2:G2000)="n/a")+(LOWER('Moodle-Cloudlabs Integration'!G2:G2000)="not applicable"))),0) -> 0 | K24: Yes | L24: =IF(I24=0,0,J24/I24) -> 0
A25: 16 | B25: LTI and SSO Integration | C25: =COUNTA('LTI and SSO Integration'!B2:B2000) -> 5 | D25: =COUNTIF('LTI and SSO Integration'!J2:J2000,"Smoke") -> 0 | E25: =COUNTIF('LTI and SSO Integration'!J2:J2000,"Core") -> 0 | F25: =COUNTIF('LTI and SSO Integration'!J2:J2000,"Extended") -> 5 | I25: =D25+IF(G25="Yes",E25,0) -> 0 | J25: =SUMPRODUCT(('LTI and SSO Integration'!J2:J2000="Smoke")*((LOWER('LTI and SSO Integration'!G2:G2000)="pass")+(LOWER('LTI and SSO Integration'!G2:G2000)="fail")+(LOWER('LTI and SSO Integration'!G2:G2000)="failed")+(LOWER('LTI and SSO Integration'!G2:G2000)="blocked")+(LOWER('LTI and SSO Integration'!G2:G2000)="na")+(LOWER('LTI and SSO Integration'!G2:G2000)="n/a")+(LOWER('LTI and SSO Integration'!G2:G2000)="not applicable")))+IF(G25="Yes",SUMPRODUCT(('LTI and SSO Integration'!J2:J2000="Core")*((LOWER('LTI and SSO Integration'!G2:G2000)="pass")+(LOWER('LTI and SSO Integration'!G2:G2000)="fail")+(LOWER('LTI and SSO Integration'!G2:G2000)="failed")+(LOWER('LTI and SSO Integration'!G2:G2000)="blocked")+(LOWER('LTI and SSO Integration'!G2:G2000)="na")+(LOWER('LTI and SSO Integration'!G2:G2000)="n/a")+(LOWER('LTI and SSO Integration'!G2:G2000)="not applicable"))),0) -> 0 | K25: NS | L25: =IF(I25=0,0,J25/I25) -> 0
A26: 17 | B26: Moodle settings | C26: =COUNTA('Moodle settings'!B2:B2000) -> 80 | D26: =COUNTIF('Moodle settings'!J2:J2000,"Smoke") -> 0 | E26: =COUNTIF('Moodle settings'!J2:J2000,"Core") -> 77 | F26: =COUNTIF('Moodle settings'!J2:J2000,"Extended") -> 3 | I26: =D26+IF(G26="Yes",E26,0) -> 0 | J26: =SUMPRODUCT(('Moodle settings'!J2:J2000="Smoke")*((LOWER('Moodle settings'!G2:G2000)="pass")+(LOWER('Moodle settings'!G2:G2000)="fail")+(LOWER('Moodle settings'!G2:G2000)="failed")+(LOWER('Moodle settings'!G2:G2000)="blocked")+(LOWER('Moodle settings'!G2:G2000)="na")+(LOWER('Moodle settings'!G2:G2000)="n/a")+(LOWER('Moodle settings'!G2:G2000)="not applicable")))+IF(G26="Yes",SUMPRODUCT(('Moodle settings'!J2:J2000="Core")*((LOWER('Moodle settings'!G2:G2000)="pass")+(LOWER('Moodle settings'!G2:G2000)="fail")+(LOWER('Moodle settings'!G2:G2000)="failed")+(LOWER('Moodle settings'!G2:G2000)="blocked")+(LOWER('Moodle settings'!G2:G2000)="na")+(LOWER('Moodle settings'!G2:G2000)="n/a")+(LOWER('Moodle settings'!G2:G2000)="not applicable"))),0) -> 0 | K26: Yes | L26: =IF(I26=0,0,J26/I26) -> 0
A27: 18 | B27: Activities | C27: =COUNTA('Activities'!B2:B2000) -> 67 | D27: =COUNTIF('Activities'!J2:J2000,"Smoke") -> 10 | E27: =COUNTIF('Activities'!J2:J2000,"Core") -> 55 | F27: =COUNTIF('Activities'!J2:J2000,"Extended") -> 2 | I27: =D27+IF(G27="Yes",E27,0) -> 10 | J27: =SUMPRODUCT(('Activities'!J2:J2000="Smoke")*((LOWER('Activities'!G2:G2000)="pass")+(LOWER('Activities'!G2:G2000)="fail")+(LOWER('Activities'!G2:G2000)="failed")+(LOWER('Activities'!G2:G2000)="blocked")+(LOWER('Activities'!G2:G2000)="na")+(LOWER('Activities'!G2:G2000)="n/a")+(LOWER('Activities'!G2:G2000)="not applicable")))+IF(G27="Yes",SUMPRODUCT(('Activities'!J2:J2000="Core")*((LOWER('Activities'!G2:G2000)="pass")+(LOWER('Activities'!G2:G2000)="fail")+(LOWER('Activities'!G2:G2000)="failed")+(LOWER('Activities'!G2:G2000)="blocked")+(LOWER('Activities'!G2:G2000)="na")+(LOWER('Activities'!G2:G2000)="n/a")+(LOWER('Activities'!G2:G2000)="not applicable"))),0) -> 10 | K27: NS | L27: =IF(I27=0,0,J27/I27) -> 1
A28: 19 | B28: AWS_Marketplace_Integration | C28: =COUNTA('AWS_Marketplace_Integration'!B2:B2000) -> 39 | D28: =COUNTIF('AWS_Marketplace_Integration'!J2:J2000,"Smoke") -> 2 | E28: =COUNTIF('AWS_Marketplace_Integration'!J2:J2000,"Core") -> 32 | F28: =COUNTIF('AWS_Marketplace_Integration'!J2:J2000,"Extended") -> 2 | I28: =D28+IF(G28="Yes",E28,0) -> 2 | J28: =SUMPRODUCT(('AWS_Marketplace_Integration'!J2:J2000="Smoke")*((LOWER('AWS_Marketplace_Integration'!G2:G2000)="pass")+(LOWER('AWS_Marketplace_Integration'!G2:G2000)="fail")+(LOWER('AWS_Marketplace_Integration'!G2:G2000)="failed")+(LOWER('AWS_Marketplace_Integration'!G2:G2000)="blocked")+(LOWER('AWS_Marketplace_Integration'!G2:G2000)="na")+(LOWER('AWS_Marketplace_Integration'!G2:G2000)="n/a")+(LOWER('AWS_Marketplace_Integration'!G2:G2000)="not applicable")))+IF(G28="Yes",SUMPRODUCT(('AWS_Marketplace_Integration'!J2:J2000="Core")*((LOWER('AWS_Marketplace_Integration'!G2:G2000)="pass")+(LOWER('AWS_Marketplace_Integration'!G2:G2000)="fail")+(LOWER('AWS_Marketplace_Integration'!G2:G2000)="failed")+(LOWER('AWS_Marketplace_Integration'!G2:G2000)="blocked")+(LOWER('AWS_Marketplace_Integration'!G2:G2000)="na")+(LOWER('AWS_Marketplace_Integration'!G2:G2000)="n/a")+(LOWER('AWS_Marketplace_Integration'!G2:G2000)="not applicable"))),0) -> 0 | K28: NS | L28: =IF(I28=0,0,J28/I28) -> 0
A29: 20 | B29: Lab_Creation_Region_Based | C29: =COUNTA('Lab_Creation_Region_Based'!B2:B2000) -> 23 | D29: =COUNTIF('Lab_Creation_Region_Based'!J2:J2000,"Smoke") -> 0 | E29: =COUNTIF('Lab_Creation_Region_Based'!J2:J2000,"Core") -> 21 | F29: =COUNTIF('Lab_Creation_Region_Based'!J2:J2000,"Extended") -> 2 | I29: =D29+IF(G29="Yes",E29,0) -> 0 | J29: =SUMPRODUCT(('Lab_Creation_Region_Based'!J2:J2000="Smoke")*((LOWER('Lab_Creation_Region_Based'!G2:G2000)="pass")+(LOWER('Lab_Creation_Region_Based'!G2:G2000)="fail")+(LOWER('Lab_Creation_Region_Based'!G2:G2000)="failed")+(LOWER('Lab_Creation_Region_Based'!G2:G2000)="blocked")+(LOWER('Lab_Creation_Region_Based'!G2:G2000)="na")+(LOWER('Lab_Creation_Region_Based'!G2:G2000)="n/a")+(LOWER('Lab_Creation_Region_Based'!G2:G2000)="not applicable")))+IF(G29="Yes",SUMPRODUCT(('Lab_Creation_Region_Based'!J2:J2000="Core")*((LOWER('Lab_Creation_Region_Based'!G2:G2000)="pass")+(LOWER('Lab_Creation_Region_Based'!G2:G2000)="fail")+(LOWER('Lab_Creation_Region_Based'!G2:G2000)="failed")+(LOWER('Lab_Creation_Region_Based'!G2:G2000)="blocked")+(LOWER('Lab_Creation_Region_Based'!G2:G2000)="na")+(LOWER('Lab_Creation_Region_Based'!G2:G2000)="n/a")+(LOWER('Lab_Creation_Region_Based'!G2:G2000)="not applicable"))),0) -> 0 | K29: NS | L29: =IF(I29=0,0,J29/I29) -> 0
A30: 21 | B30: Randomization_Activity | C30: =COUNTA('Randomization_Activity'!B2:B2000) -> 71 | D30: =COUNTIF('Randomization_Activity'!J2:J2000,"Smoke") -> 5 | E30: =COUNTIF('Randomization_Activity'!J2:J2000,"Core") -> 55 | F30: =COUNTIF('Randomization_Activity'!J2:J2000,"Extended") -> 8 | I30: =D30+IF(G30="Yes",E30,0) -> 5 | J30: =SUMPRODUCT(('Randomization_Activity'!J2:J2000="Smoke")*((LOWER('Randomization_Activity'!G2:G2000)="pass")+(LOWER('Randomization_Activity'!G2:G2000)="fail")+(LOWER('Randomization_Activity'!G2:G2000)="failed")+(LOWER('Randomization_Activity'!G2:G2000)="blocked")+(LOWER('Randomization_Activity'!G2:G2000)="na")+(LOWER('Randomization_Activity'!G2:G2000)="n/a")+(LOWER('Randomization_Activity'!G2:G2000)="not applicable")))+IF(G30="Yes",SUMPRODUCT(('Randomization_Activity'!J2:J2000="Core")*((LOWER('Randomization_Activity'!G2:G2000)="pass")+(LOWER('Randomization_Activity'!G2:G2000)="fail")+(LOWER('Randomization_Activity'!G2:G2000)="failed")+(LOWER('Randomization_Activity'!G2:G2000)="blocked")+(LOWER('Randomization_Activity'!G2:G2000)="na")+(LOWER('Randomization_Activity'!G2:G2000)="n/a")+(LOWER('Randomization_Activity'!G2:G2000)="not applicable"))),0) -> 5 | K30: NS | L30: =IF(I30=0,0,J30/I30) -> 1
A31: 22 | B31: Raven360_AWS_Content | C31: =COUNTA('Raven360_AWS_Content'!B2:B2000) -> 29 | D31: =COUNTIF('Raven360_AWS_Content'!J2:J2000,"Smoke") -> 4 | E31: =COUNTIF('Raven360_AWS_Content'!J2:J2000,"Core") -> 23 | F31: =COUNTIF('Raven360_AWS_Content'!J2:J2000,"Extended") -> 2 | I31: =D31+IF(G31="Yes",E31,0) -> 4 | J31: =SUMPRODUCT(('Raven360_AWS_Content'!J2:J2000="Smoke")*((LOWER('Raven360_AWS_Content'!G2:G2000)="pass")+(LOWER('Raven360_AWS_Content'!G2:G2000)="fail")+(LOWER('Raven360_AWS_Content'!G2:G2000)="failed")+(LOWER('Raven360_AWS_Content'!G2:G2000)="blocked")+(LOWER('Raven360_AWS_Content'!G2:G2000)="na")+(LOWER('Raven360_AWS_Content'!G2:G2000)="n/a")+(LOWER('Raven360_AWS_Content'!G2:G2000)="not applicable")))+IF(G31="Yes",SUMPRODUCT(('Raven360_AWS_Content'!J2:J2000="Core")*((LOWER('Raven360_AWS_Content'!G2:G2000)="pass")+(LOWER('Raven360_AWS_Content'!G2:G2000)="fail")+(LOWER('Raven360_AWS_Content'!G2:G2000)="failed")+(LOWER('Raven360_AWS_Content'!G2:G2000)="blocked")+(LOWER('Raven360_AWS_Content'!G2:G2000)="na")+(LOWER('Raven360_AWS_Content'!G2:G2000)="n/a")+(LOWER('Raven360_AWS_Content'!G2:G2000)="not applicable"))),0) -> 1 | K31: NS | L31: =IF(I31=0,0,J31/I31) -> 0.25
A32: 23 | B32: Course_Category_Lab_Provision | C32: =COUNTA('Course_Category_Lab_Provision'!B2:B2000) -> 12 | D32: =COUNTIF('Course_Category_Lab_Provision'!J2:J2000,"Smoke") -> 0 | E32: =COUNTIF('Course_Category_Lab_Provision'!J2:J2000,"Core") -> 10 | F32: =COUNTIF('Course_Category_Lab_Provision'!J2:J2000,"Extended") -> 2 | I32: =D32+IF(G32="Yes",E32,0) -> 0 | J32: =SUMPRODUCT(('Course_Category_Lab_Provision'!J2:J2000="Smoke")*((LOWER('Course_Category_Lab_Provision'!G2:G2000)="pass")+(LOWER('Course_Category_Lab_Provision'!G2:G2000)="fail")+(LOWER('Course_Category_Lab_Provision'!G2:G2000)="failed")+(LOWER('Course_Category_Lab_Provision'!G2:G2000)="blocked")+(LOWER('Course_Category_Lab_Provision'!G2:G2000)="na")+(LOWER('Course_Category_Lab_Provision'!G2:G2000)="n/a")+(LOWER('Course_Category_Lab_Provision'!G2:G2000)="not applicable")))+IF(G32="Yes",SUMPRODUCT(('Course_Category_Lab_Provision'!J2:J2000="Core")*((LOWER('Course_Category_Lab_Provision'!G2:G2000)="pass")+(LOWER('Course_Category_Lab_Provision'!G2:G2000)="fail")+(LOWER('Course_Category_Lab_Provision'!G2:G2000)="failed")+(LOWER('Course_Category_Lab_Provision'!G2:G2000)="blocked")+(LOWER('Course_Category_Lab_Provision'!G2:G2000)="na")+(LOWER('Course_Category_Lab_Provision'!G2:G2000)="n/a")+(LOWER('Course_Category_Lab_Provision'!G2:G2000)="not applicable"))),0) -> 0 | K32: NS | L32: =IF(I32=0,0,J32/I32) -> 0
A33: 24 | B33: Stop_Lab_Enhancement | C33: =COUNTA('Stop_Lab_Enhancement'!B2:B2000) -> 7 | D33: =COUNTIF('Stop_Lab_Enhancement'!J2:J2000,"Smoke") -> 3 | E33: =COUNTIF('Stop_Lab_Enhancement'!J2:J2000,"Core") -> 1 | F33: =COUNTIF('Stop_Lab_Enhancement'!J2:J2000,"Extended") -> 3 | I33: =D33+IF(G33="Yes",E33,0) -> 3 | J33: =SUMPRODUCT(('Stop_Lab_Enhancement'!J2:J2000="Smoke")*((LOWER('Stop_Lab_Enhancement'!G2:G2000)="pass")+(LOWER('Stop_Lab_Enhancement'!G2:G2000)="fail")+(LOWER('Stop_Lab_Enhancement'!G2:G2000)="failed")+(LOWER('Stop_Lab_Enhancement'!G2:G2000)="blocked")+(LOWER('Stop_Lab_Enhancement'!G2:G2000)="na")+(LOWER('Stop_Lab_Enhancement'!G2:G2000)="n/a")+(LOWER('Stop_Lab_Enhancement'!G2:G2000)="not applicable")))+IF(G33="Yes",SUMPRODUCT(('Stop_Lab_Enhancement'!J2:J2000="Core")*((LOWER('Stop_Lab_Enhancement'!G2:G2000)="pass")+(LOWER('Stop_Lab_Enhancement'!G2:G2000)="fail")+(LOWER('Stop_Lab_Enhancement'!G2:G2000)="failed")+(LOWER('Stop_Lab_Enhancement'!G2:G2000)="blocked")+(LOWER('Stop_Lab_Enhancement'!G2:G2000)="na")+(LOWER('Stop_Lab_Enhancement'!G2:G2000)="n/a")+(LOWER('Stop_Lab_Enhancement'!G2:G2000)="not applicable"))),0) -> 3 | K33: NS | L33: =IF(I33=0,0,J33/I33) -> 1
A34: 25 | B34: Difficulty_Level_Configuration | C34: =COUNTA('Difficulty_Level_Configuration'!B2:B2000) -> 16 | D34: =COUNTIF('Difficulty_Level_Configuration'!J2:J2000,"Smoke") -> 0 | E34: =COUNTIF('Difficulty_Level_Configuration'!J2:J2000,"Core") -> 11 | F34: =COUNTIF('Difficulty_Level_Configuration'!J2:J2000,"Extended") -> 2 | I34: =D34+IF(G34="Yes",E34,0) -> 0 | J34: =SUMPRODUCT(('Difficulty_Level_Configuration'!J2:J2000="Smoke")*((LOWER('Difficulty_Level_Configuration'!G2:G2000)="pass")+(LOWER('Difficulty_Level_Configuration'!G2:G2000)="fail")+(LOWER('Difficulty_Level_Configuration'!G2:G2000)="failed")+(LOWER('Difficulty_Level_Configuration'!G2:G2000)="blocked")+(LOWER('Difficulty_Level_Configuration'!G2:G2000)="na")+(LOWER('Difficulty_Level_Configuration'!G2:G2000)="n/a")+(LOWER('Difficulty_Level_Configuration'!G2:G2000)="not applicable")))+IF(G34="Yes",SUMPRODUCT(('Difficulty_Level_Configuration'!J2:J2000="Core")*((LOWER('Difficulty_Level_Configuration'!G2:G2000)="pass")+(LOWER('Difficulty_Level_Configuration'!G2:G2000)="fail")+(LOWER('Difficulty_Level_Configuration'!G2:G2000)="failed")+(LOWER('Difficulty_Level_Configuration'!G2:G2000)="blocked")+(LOWER('Difficulty_Level_Configuration'!G2:G2000)="na")+(LOWER('Difficulty_Level_Configuration'!G2:G2000)="n/a")+(LOWER('Difficulty_Level_Configuration'!G2:G2000)="not applicable"))),0) -> 0 | K34: Yes | L34: =IF(I34=0,0,J34/I34) -> 0
A35: 26 | B35: Lab_Control_Panel | C35: =COUNTA('Lab_Control_Panel'!B2:B2000) -> 34 | D35: =COUNTIF('Lab_Control_Panel'!J2:J2000,"Smoke") -> 4 | E35: =COUNTIF('Lab_Control_Panel'!J2:J2000,"Core") -> 27 | F35: =COUNTIF('Lab_Control_Panel'!J2:J2000,"Extended") -> 3 | I35: =D35+IF(G35="Yes",E35,0) -> 4 | J35: =SUMPRODUCT(('Lab_Control_Panel'!J2:J2000="Smoke")*((LOWER('Lab_Control_Panel'!G2:G2000)="pass")+(LOWER('Lab_Control_Panel'!G2:G2000)="fail")+(LOWER('Lab_Control_Panel'!G2:G2000)="failed")+(LOWER('Lab_Control_Panel'!G2:G2000)="blocked")+(LOWER('Lab_Control_Panel'!G2:G2000)="na")+(LOWER('Lab_Control_Panel'!G2:G2000)="n/a")+(LOWER('Lab_Control_Panel'!G2:G2000)="not applicable")))+IF(G35="Yes",SUMPRODUCT(('Lab_Control_Panel'!J2:J2000="Core")*((LOWER('Lab_Control_Panel'!G2:G2000)="pass")+(LOWER('Lab_Control_Panel'!G2:G2000)="fail")+(LOWER('Lab_Control_Panel'!G2:G2000)="failed")+(LOWER('Lab_Control_Panel'!G2:G2000)="blocked")+(LOWER('Lab_Control_Panel'!G2:G2000)="na")+(LOWER('Lab_Control_Panel'!G2:G2000)="n/a")+(LOWER('Lab_Control_Panel'!G2:G2000)="not applicable"))),0) -> 0 | K35: NS | L35: =IF(I35=0,0,J35/I35) -> 0
A36: 27 | B36: Content_Integration_Git_URL | C36: =COUNTA('Content_Integration_Git_URL'!B2:B2000) -> 26 | D36: =COUNTIF('Content_Integration_Git_URL'!J2:J2000,"Smoke") -> 0 | E36: =COUNTIF('Content_Integration_Git_URL'!J2:J2000,"Core") -> 21 | F36: =COUNTIF('Content_Integration_Git_URL'!J2:J2000,"Extended") -> 3 | I36: =D36+IF(G36="Yes",E36,0) -> 0 | J36: =SUMPRODUCT(('Content_Integration_Git_URL'!J2:J2000="Smoke")*((LOWER('Content_Integration_Git_URL'!G2:G2000)="pass")+(LOWER('Content_Integration_Git_URL'!G2:G2000)="fail")+(LOWER('Content_Integration_Git_URL'!G2:G2000)="failed")+(LOWER('Content_Integration_Git_URL'!G2:G2000)="blocked")+(LOWER('Content_Integration_Git_URL'!G2:G2000)="na")+(LOWER('Content_Integration_Git_URL'!G2:G2000)="n/a")+(LOWER('Content_Integration_Git_URL'!G2:G2000)="not applicable")))+IF(G36="Yes",SUMPRODUCT(('Content_Integration_Git_URL'!J2:J2000="Core")*((LOWER('Content_Integration_Git_URL'!G2:G2000)="pass")+(LOWER('Content_Integration_Git_URL'!G2:G2000)="fail")+(LOWER('Content_Integration_Git_URL'!G2:G2000)="failed")+(LOWER('Content_Integration_Git_URL'!G2:G2000)="blocked")+(LOWER('Content_Integration_Git_URL'!G2:G2000)="na")+(LOWER('Content_Integration_Git_URL'!G2:G2000)="n/a")+(LOWER('Content_Integration_Git_URL'!G2:G2000)="not applicable"))),0) -> 0 | K36: Yes | L36: =IF(I36=0,0,J36/I36) -> 0
A37: 28 | B37: Course_Sync_Multi_Tenant | C37: =COUNTA('Course_Sync_Multi_Tenant'!B2:B2000) -> 33 | D37: =COUNTIF('Course_Sync_Multi_Tenant'!J2:J2000,"Smoke") -> 3 | E37: =COUNTIF('Course_Sync_Multi_Tenant'!J2:J2000,"Core") -> 28 | F37: =COUNTIF('Course_Sync_Multi_Tenant'!J2:J2000,"Extended") -> 2 | I37: =D37+IF(G37="Yes",E37,0) -> 3 | J37: =SUMPRODUCT(('Course_Sync_Multi_Tenant'!J2:J2000="Smoke")*((LOWER('Course_Sync_Multi_Tenant'!G2:G2000)="pass")+(LOWER('Course_Sync_Multi_Tenant'!G2:G2000)="fail")+(LOWER('Course_Sync_Multi_Tenant'!G2:G2000)="failed")+(LOWER('Course_Sync_Multi_Tenant'!G2:G2000)="blocked")+(LOWER('Course_Sync_Multi_Tenant'!G2:G2000)="na")+(LOWER('Course_Sync_Multi_Tenant'!G2:G2000)="n/a")+(LOWER('Course_Sync_Multi_Tenant'!G2:G2000)="not applicable")))+IF(G37="Yes",SUMPRODUCT(('Course_Sync_Multi_Tenant'!J2:J2000="Core")*((LOWER('Course_Sync_Multi_Tenant'!G2:G2000)="pass")+(LOWER('Course_Sync_Multi_Tenant'!G2:G2000)="fail")+(LOWER('Course_Sync_Multi_Tenant'!G2:G2000)="failed")+(LOWER('Course_Sync_Multi_Tenant'!G2:G2000)="blocked")+(LOWER('Course_Sync_Multi_Tenant'!G2:G2000)="na")+(LOWER('Course_Sync_Multi_Tenant'!G2:G2000)="n/a")+(LOWER('Course_Sync_Multi_Tenant'!G2:G2000)="not applicable"))),0) -> 0 | K37: NS | L37: =IF(I37=0,0,J37/I37) -> 0
A38: 29 | B38: My_Labs | C38: =COUNTA('My_Labs'!B2:B2000) -> 44 | D38: =COUNTIF('My_Labs'!J2:J2000,"Smoke") -> 3 | E38: =COUNTIF('My_Labs'!J2:J2000,"Core") -> 32 | F38: =COUNTIF('My_Labs'!J2:J2000,"Extended") -> 6 | I38: =D38+IF(G38="Yes",E38,0) -> 3 | J38: =SUMPRODUCT(('My_Labs'!J2:J2000="Smoke")*((LOWER('My_Labs'!G2:G2000)="pass")+(LOWER('My_Labs'!G2:G2000)="fail")+(LOWER('My_Labs'!G2:G2000)="failed")+(LOWER('My_Labs'!G2:G2000)="blocked")+(LOWER('My_Labs'!G2:G2000)="na")+(LOWER('My_Labs'!G2:G2000)="n/a")+(LOWER('My_Labs'!G2:G2000)="not applicable")))+IF(G38="Yes",SUMPRODUCT(('My_Labs'!J2:J2000="Core")*((LOWER('My_Labs'!G2:G2000)="pass")+(LOWER('My_Labs'!G2:G2000)="fail")+(LOWER('My_Labs'!G2:G2000)="failed")+(LOWER('My_Labs'!G2:G2000)="blocked")+(LOWER('My_Labs'!G2:G2000)="na")+(LOWER('My_Labs'!G2:G2000)="n/a")+(LOWER('My_Labs'!G2:G2000)="not applicable"))),0) -> 2 | K38: Yes | L38: =IF(I38=0,0,J38/I38) -> 0.66666667
A39: 30 | B39: NuveBulkMail | C39: =COUNTA('NuveBulkMail'!B2:B2000) -> 113 | D39: =COUNTIF('NuveBulkMail'!J2:J2000,"Smoke") -> 4 | E39: =COUNTIF('NuveBulkMail'!J2:J2000,"Core") -> 84 | F39: =COUNTIF('NuveBulkMail'!J2:J2000,"Extended") -> 22 | I39: =D39+IF(G39="Yes",E39,0) -> 4 | J39: =SUMPRODUCT(('NuveBulkMail'!J2:J2000="Smoke")*((LOWER('NuveBulkMail'!G2:G2000)="pass")+(LOWER('NuveBulkMail'!G2:G2000)="fail")+(LOWER('NuveBulkMail'!G2:G2000)="failed")+(LOWER('NuveBulkMail'!G2:G2000)="blocked")+(LOWER('NuveBulkMail'!G2:G2000)="na")+(LOWER('NuveBulkMail'!G2:G2000)="n/a")+(LOWER('NuveBulkMail'!G2:G2000)="not applicable")))+IF(G39="Yes",SUMPRODUCT(('NuveBulkMail'!J2:J2000="Core")*((LOWER('NuveBulkMail'!G2:G2000)="pass")+(LOWER('NuveBulkMail'!G2:G2000)="fail")+(LOWER('NuveBulkMail'!G2:G2000)="failed")+(LOWER('NuveBulkMail'!G2:G2000)="blocked")+(LOWER('NuveBulkMail'!G2:G2000)="na")+(LOWER('NuveBulkMail'!G2:G2000)="n/a")+(LOWER('NuveBulkMail'!G2:G2000)="not applicable"))),0) -> 0 | K39: NS | L39: =IF(I39=0,0,J39/I39) -> 0
A40: 31 | B40: Pre_Delivery_Lab_Checklist | C40: =COUNTA('Pre_Delivery_Lab_Checklist'!B2:B2000) -> 76 | D40: =COUNTIF('Pre_Delivery_Lab_Checklist'!J2:J2000,"Smoke") -> 1 | E40: =COUNTIF('Pre_Delivery_Lab_Checklist'!J2:J2000,"Core") -> 63 | F40: =COUNTIF('Pre_Delivery_Lab_Checklist'!J2:J2000,"Extended") -> 8 | I40: =D40+IF(G40="Yes",E40,0) -> 1 | J40: =SUMPRODUCT(('Pre_Delivery_Lab_Checklist'!J2:J2000="Smoke")*((LOWER('Pre_Delivery_Lab_Checklist'!G2:G2000)="pass")+(LOWER('Pre_Delivery_Lab_Checklist'!G2:G2000)="fail")+(LOWER('Pre_Delivery_Lab_Checklist'!G2:G2000)="failed")+(LOWER('Pre_Delivery_Lab_Checklist'!G2:G2000)="blocked")+(LOWER('Pre_Delivery_Lab_Checklist'!G2:G2000)="na")+(LOWER('Pre_Delivery_Lab_Checklist'!G2:G2000)="n/a")+(LOWER('Pre_Delivery_Lab_Checklist'!G2:G2000)="not applicable")))+IF(G40="Yes",SUMPRODUCT(('Pre_Delivery_Lab_Checklist'!J2:J2000="Core")*((LOWER('Pre_Delivery_Lab_Checklist'!G2:G2000)="pass")+(LOWER('Pre_Delivery_Lab_Checklist'!G2:G2000)="fail")+(LOWER('Pre_Delivery_Lab_Checklist'!G2:G2000)="failed")+(LOWER('Pre_Delivery_Lab_Checklist'!G2:G2000)="blocked")+(LOWER('Pre_Delivery_Lab_Checklist'!G2:G2000)="na")+(LOWER('Pre_Delivery_Lab_Checklist'!G2:G2000)="n/a")+(LOWER('Pre_Delivery_Lab_Checklist'!G2:G2000)="not applicable"))),0) -> 1 | K40: NS | L40: =IF(I40=0,0,J40/I40) -> 1
A41: 32 | B41: Sequential_Activity_Completion | C41: =COUNTA('Sequential_Activity_Completion'!B2:B2000) -> 28 | D41: =COUNTIF('Sequential_Activity_Completion'!J2:J2000,"Smoke") -> 0 | E41: =COUNTIF('Sequential_Activity_Completion'!J2:J2000,"Core") -> 11 | F41: =COUNTIF('Sequential_Activity_Completion'!J2:J2000,"Extended") -> 5 | I41: =D41+IF(G41="Yes",E41,0) -> 0 | J41: =SUMPRODUCT(('Sequential_Activity_Completion'!J2:J2000="Smoke")*((LOWER('Sequential_Activity_Completion'!G2:G2000)="pass")+(LOWER('Sequential_Activity_Completion'!G2:G2000)="fail")+(LOWER('Sequential_Activity_Completion'!G2:G2000)="failed")+(LOWER('Sequential_Activity_Completion'!G2:G2000)="blocked")+(LOWER('Sequential_Activity_Completion'!G2:G2000)="na")+(LOWER('Sequential_Activity_Completion'!G2:G2000)="n/a")+(LOWER('Sequential_Activity_Completion'!G2:G2000)="not applicable")))+IF(G41="Yes",SUMPRODUCT(('Sequential_Activity_Completion'!J2:J2000="Core")*((LOWER('Sequential_Activity_Completion'!G2:G2000)="pass")+(LOWER('Sequential_Activity_Completion'!G2:G2000)="fail")+(LOWER('Sequential_Activity_Completion'!G2:G2000)="failed")+(LOWER('Sequential_Activity_Completion'!G2:G2000)="blocked")+(LOWER('Sequential_Activity_Completion'!G2:G2000)="na")+(LOWER('Sequential_Activity_Completion'!G2:G2000)="n/a")+(LOWER('Sequential_Activity_Completion'!G2:G2000)="not applicable"))),0) -> 0 | K41: Yes | L41: =IF(I41=0,0,J41/I41) -> 0
...

Sheet Automation_Coverage
A1: Sheet | B1: Automated (Yes) | C1: Partial | D1: Deviation (finding) | E1: Deferred (gap) | F1: Not automated | G1: Total cases | H1: % automated
A2: Moodle_users | B2: 32 | C2: 0 | D2: 0 | E2: 0 | F2: 17 | G2: 49 | H2: 100%
A3: Upload_Users | B3: 43 | C3: 0 | D3: 0 | E3: 0 | F3: 5 | G3: 48 | H3: 100%
A4: Moodle_Tags | B4: 38 | C4: 2 | D4: 0 | E4: 0 | F4: 14 | G4: 54 | H4: 95%
A5: Moodle_Roles | B5: 62 | C5: 1 | D5: 0 | E5: 0 | F5: 26 | G5: 89 | H5: 98%
A6: Groups_Testcases | B6: 19 | C6: 5 | D6: 0 | E6: 0 | F6: 35 | G6: 59 | H6: 79%
A7: Moodle_Assessment_Labs | B7: 163 | C7: 133 | D7: 3 | E7: 47 | F7: 20 | G7: 366 | H7: 47%
A8: Practice_Project | B8: 72 | C8: 23 | D8: 36 | E8: 0 | F8: 79 | G8: 210 | H8: 55%
A9: Moodle_Sandbox_Labs | B9: 53 | C9: 0 | D9: 0 | E9: 0 | F9: 9 | G9: 62 | H9: 100%
A10: All Course Page | B10: 95 | C10: 0 | D10: 0 | E10: 0 | F10: 15 | G10: 110 | H10: 100%
A11: Pre_Delivery_Lab_Checklist | B11: 63 | C11: 8 | D11: 0 | E11: 0 | F11: 5 | G11: 76 | H11: 89%
A12: NuveBulkMail | B12: 6 | C12: 0 | D12: 0 | E12: 3 | F12: 104 | G12: 113 | H12: 67%
A13: AWS_Marketplace_Integration | B13: 5 | C13: 0 | D13: 1 | E13: 2 | F13: 31 | G13: 39 | H13: 62%
... A23: TOTAL (worked sheets) | B23: 738 | C23: 176 | D23: 43 | E23: 57 | F23: 459 | G23: 1473 | H23: 50%
A25: Legend: Yes=green test verifies this case | Partial=partly covered (see ref) | Deviation=fail-by-design finding | Deferred=derived gap not yet automated | No=not automated (ref=reason)
A26: Note: per-case marking is by judgement (a scenario can cover several cases). Sheets not listed here are 0% automated.

Sheet Moodle_users
A1: Title | B1: Summary | C1: Preconditions | D1: Product | E1: Category | F1: Priority | G1: Case_Status | H1: Steps | I1: Expected | J1: Regression_Tier | K1: Automated | L1: Automation_Ref
A2: User Registration: | B2: Verify that a new user can register successfully by admin | C2: Admin Access | D2: Moodle | E2: Moodle_users | F2: High | G2: Pass | H2: AUTOMATED - verified by moodle_users.feature @users. (Manual steps below may be inaccurate; the test is the source of truth.) --- 1)Login as admin 2)Click on site administration 3) Click on users 4)Click on add new user 5)Verify that admin can register new user | I2: Admin must be able to register new user | J2: Smoke | K2: Yes | L2: moodle_users.feature @U-user-1
A3: User Registration: | B3: Check that all mandatory fields (username, password, email, etc.) are required during registration | C3: Admin Access | D3: Moodle | E3: Moodle_users | F3: High | G3: Pass | H3: AUTOMATED - verified by @users. (Manual steps below may be inaccurate; the test is the source of truth.) --- 1)Login as admin 2)Click on site administration 3) Click on users 4)Click on add new user 5)Verify that username, password, email are mandatory | I3: All the mandatory fields are req during the registration | J3: Core | K3: Yes | L3: moodle_users.feature @U-user-2
A4: User Registration: | B4: Test the system's response when a user tries to register with an existing username or email. | C4: Admin Access | D4: Moodle | E4: Moodle_users | F4: High | G4: Pass | H4: AUTOMATED - verified by @users. (Manual steps below may be inaccurate; the test is the source of truth.) --- 1)Login as admin 2)Click on site administration 3) Click on users 4)Click on add new user 5) Enter the username or email that already exists 6) Verify that admin can use the already regissted username | I4: The system must throw an error saying user already exists | J4: Smoke | K4: Yes | L4: moodle_users.feature @U-user-5
A5: User Registration: | B5: Ensure that password complexity requirements are enforced | C5: Admin Access | D5: Moodle | E5: Moodle_users | F5: High | G5: Pass | H5: AUTOMATED - verified by @users. (Manual steps below may be inaccurate; the test is the source of truth.) --- 1)Login as admin 2)Click on site administration 3) Click on users 4)Click on add new user 5) Verify that password complexity requirements are enforced | I5: Password entered must satisfy the complexity req otherwise sysytem must throw an error | J5: Core | K5: Yes | L5: moodle_users.feature @U-user-3
A6: User Login | B6: Verify that registered users can log in with valid credentials | C6: Admin Access | D6: Moodle | E6: Moodle_users | F6: High | G6: Pass | H6: AUTOMATED (moodle_users.feature :: A registered user can log in with valid credentials) Given a registered user Then the user can log in with valid credentials | I6: The registered users must be able to login with the valid credentials | J6: Smoke | K6: Yes | L6: moodle_users.feature @U-user-7
A7: User Login | B7: Test the system's response when a user enters incorrect credentials. | C7: Admin Access | D7: Moodle | E7: Moodle_users | F7: High | G7: Pass | H7: AUTOMATED - verified by @users. (Manual steps below may be inaccurate; the test is the source of truth.) --- 1) Click on the site url 2) try login with wrong username or password 2) Verify that system's response when a user enters incorrect credentials. | I7: System must throw proper error saying invalid credentials | J7: Smoke | K7: Yes | L7: moodle_users.feature @U-user-8
A8: User Login | B8: Check for the "Remember Me" functionality. | C8: Admin Access | D8: Moodle | E8: Moodle_users | F8: High | G8: NA | H8: 1)Click on site url 2) click on remember me option 3) Verify that the rememberfunction is working correctly | I8: When remember me is selected username of the user must be stored by the browser | J8: Smoke | K8: No | L8: No — not automatable (mail/config/paid-enrol/activity-overlap/bulk-CSV/auth-plugin)
A9: User Login | B9: Verify that the system locks the account temporarily after a certain number of consecutive failed login attempts. | C9: Admin Access | D9: Moodle | E9: Moodle_users | F9: High | G9: Pass | H9: 1)Click on site url 2) try multiple login with wrong credentials 3) Verify that system locks the account temporarily after a certain number of consecutive failed login attempts. | I9: When user fails continous logins for multiple times then user profile must be locked. | J9: Core | K9: Yes | L9: moodle_users.feature @U-user-28
A10: User Login | B10: Verify the Forget Password functionality | C10: Admin Access | D10: Moodle | E10: Moodle_users | F10: High | G10: NA | H10: 1)Click on site url 2) Verify the Forget Password functionality | I10: When user clicks on forgot passwordand enters valid username/email an email to reset password is sent to respective registered mail to reset the new password | J10: Core | K10: No | L10: No — not automatable (mail/config/paid-enrol/activity-overlap/bulk-CSV/auth-plugin)
A11: User Profile | B11: Confirm that users can update their profile information (name, email, password, etc.). | C11: Admin Access | D11: Moodle | E11: Moodle_users | F11: High | G11: Pass | H11: AUTOMATED - verified by @users. (Manual steps below may be inaccurate; the test is the source of truth.) --- 1)Login as admin 2) Click on the site administration 3) Click on users 4) Click on browse users list 5) Verify that admin can update the user details | I11: Once user logs in he must be able to update his profile info accordingly | J11: Core | K11: Yes | L11: moodle_users.feature @U-user-18
A12: User Profile | B12: Check that profile updates are reflected correctly in the system | C12: Admin Access | D12: Moodle | E12: Moodle_users | F12: Medium | G12: Pass | H12: AUTOMATED - verified by @users. (Manual steps below may be inaccurate; the test is the source of truth.) --- 1)Login as admin 2) Click on the site administration 3) Click on users 4) Click on browse users list 5) Verify that admin updated user details are correctly reflected or not | I12: updates must be properly reflected | J12: Core | K12: Yes | L12: Covered by @U-user-18
... A23: Logout: | B23: Check for any session-related issues after logging out. | C23: Admin Access | D23: Moodle | E23: Moodle_users | F23: High | G23: Pass | H23: AUTOMATED - verified by @users. (Manual steps below may be inaccurate; the test is the source of truth.) --- 1) Login to the system 2)Logout from the system 3)Verify any session-related issues after logging out. | I23: There should be no session related issues after user logs out | J23: Core | K23: Yes | L23: moodle_users.feature @U-user-10
A24: Bulk Moodle user import | B24: Check if user I can be imported in bulk or not | C24: Admin Access | D24: Moodle | E24: Moodle_users | F24: Medium | G24: NA | I24: Users can be imported in bulk | J24: Core | K24: No | L24: No — not automatable (mail/config/paid-enrol/activity-overlap/bulk-CSV/auth-plugin)
A25: User workflow | B25: create a new user, delete user, edit the user details | C25: Admin Access | D25: Moodle | E25: Moodle_users | F25: High | G25: Pass | H25: AUTOMATED - verified by @users. (Manual steps below may be inaccurate; the test is the source of truth.) --- 1)Login as admin 2)Click on site administration 3) Click on users 4)Click on browse users list 5)Verify that admin can create a new user, delete user, edit the user details | I25: Admin must be able to perform all actions | J25: Core | K25: Yes | L25: moodle_users.feature @U-user-14
A26: User workflow | B26: Verify user is listing in the user listing page | C26: Admin Access | D26: Moodle | E26: Moodle_users | F26: Medium | G26: Pass | H26: AUTOMATED - verified by @users. (Manual steps below may be inaccurate; the test is the source of truth.) --- 1)Login as admin 2)Click on site administration 3) Click on users 4)Click on browse users list 5)Verify user is listing in the user listing page | I26: User must be listed after registration | J26: Core | K26: Yes | L26: moodle_users.feature @U-user-11
A27: User workflow | B27: Verify user can login to the Moodle when we disable the user at the Moodle level. | C27: Admin Access | D27: Moodle | E27: Moodle_users | F27: High | G27: Pass | H27: AUTOMATED - verified by @users. (Manual steps below may be inaccurate; the test is the source of truth.) --- 1)Login as admin 2)Click on site administration 3) Click on users 4)Click on browse list of users 5) disable the user 6) Verify that disabled user can login to the system | I27: User must not be able to login | J27: Core | K27: Yes | L27: moodle_users.feature @U-user-12
A28: User workflow | B28: Verify user can login to the Moodle when we enable the user at the Moodle level. | C28: Admin Access | D28: Moodle | E28: Moodle_users | F28: High | G28: Pass | H28: AUTOMATED - verified by @users. (Manual steps below may be inaccurate; the test is the source of truth.) --- 1)Login as admin 2)Click on site administration 3) Click on users 4)Click on browse list of users 5) Enable the user 6) Verify that enabled user can login to the system | I28: User must be able to login | J28: Core | K28: Yes | L28: Covered by @U-user-12
A29: User workflow | B29: Verify admin can create a cohort add users to the cohorts | C29: Admin Access | D29: Moodle | E29: Moodle_users | F29: Medium | G29: Pass | H29: AUTOMATED (moodle_users.feature :: Admin can create a cohort) Then admin can create a cohort that is listed | I29: Admin must be able to add users | J29: Core | K29: Yes | L29: moodle_users.feature @U-user-23
A30: User workflow | B30: Verify admin can delete the cohorts | C30: Admin Access | D30: Moodle | E30: Moodle_users | F30: Medium | G30: Pass | H30: AUTOMATED - verified by @users. (Manual steps below may be inaccurate; the test is the source of truth.) --- 1)Login as admin 2)Click on site administration 3) Click on users 4) Click on cohorts 5)Verify that admin can create the cohort and add users to cohort | I30: Admin must be able to delete | J30: Core | K30: Yes | L30: moodle_users.feature @U-user-24
A31: User workflow | B31: Email changed in moodle | C31: Admin Access | D31: Moodle | E31: Moodle_users | F31: Medium | G31: Pass | H31: AUTOMATED - verified by @users. (Manual steps below may be inaccurate; the test is the source of truth.) --- 1)Login as admin 2)Click on site administration 3) Click on users 4) Click on edit user 5) Verify that admin can change the user email | I31: Admin must be able to change the email | J31: Core | K31: Yes | L31: moodle_users.feature @U-user-13
A32: User Registration Gap Check | B32: Verify self-registration (signup) can be enabled/disabled via site policy and reflects immediately on the login page | C32: Admin access to site policies | D32: Moodle | E32: Moodle_users | F32: High | G32: NA | H32: 1) Login as admin 2) Site administration > Plugins > Authentication > Manage authentication 3) Toggle self-registration 4) Open login page as guest | I32: Self-registration link should appear/disappear according to the setting | J32: Extended | K32: No | L32: No — not automatable (mail/config/paid-enrol/activity-overlap/bulk-CSV/auth-plugin)
A33: User Registration Gap Check | B33: Verify duplicate email address (different username) is rejected during registration | C33: Admin access | D33: Moodle | E33: Moodle_users | F33: High | G33: Pass | H33: AUTOMATED (moodle_users.feature :: Duplicate email is rejected on user creation) Given a registered user When admin tries to create a user with the same email Then the form shows a duplicate-email error | I33: System should reject with a clear duplicate-email error, even though username differs | J33: Extended | K33: Yes | L33: Covered by @U-user-6
A34: User Login Gap Check | B34: Verify password reset link expires after the configured time window | C34: Password reset requested | D34: Moodle | E34: Moodle_users | F34: High | G34: NA | H34: 1) Trigger forgot-password 2) Wait past expiry window 3) Click the reset link | I34: Expired reset link should show an error and not allow password change | J34: Extended | K34: No | L34: No — not automatable (mail/config/paid-enrol/activity-overlap/bulk-CSV/auth-plugin)
A35: User Profile Gap Check | B35: Verify uploading an oversized or invalid file type as profile picture is rejected with a clear error | C35: User logged in | D35: Moodle | E35: Moodle_users | F35: Medium | G35: NA | H35: AUTOMATED (moodle_users.feature :: Invalid profile data is rejected) Given a registered user When the user saves an invalid email in their profile Then the profile form shows a validation error | I35: Upload should be rejected with an appropriate validation message | J35: Extended | K35: No | L35: No — not automatable (mail/config/paid-enrol/activity-overlap/bulk-CSV/auth-plugin)
A36: Bulk Moodle user import Gap Check | B36: Verify bulk user import (CSV) correctly reports row-level errors for malformed rows without failing the entire batch | C36: CSV with some invalid rows | D36: Moodle | E36: Moodle_users | F36: Medium | G36: NA | H36: 1) Prepare CSV with a mix of valid/invalid rows 2) Upload via bulk user upload | I36: Valid rows should be created; invalid rows should be reported individually with reasons | J36: Extended | K36: No | L36: No — not automatable (mail/config/paid-enrol/activity-overlap/bulk-CSV/auth-plugin)
A37: CGAP-U-1 | B37: Invalid email format is rejected during user creation | C37: Admin logged in | D37: Moodle | E37: Moodle_users | F37: High | G37: Pass | H37: AUTOMATED (moodle_users.feature :: Invalid email format is rejected on user creation) When admin creates a user with an invalid email format Then the form shows an email-format error | I37: Form is rejected with an email-format validation error; user is not created | K37: Yes | L37: moodle_users.feature @U-user-4
A38: CGAP-U-2 | B38: Duplicate email is rejected on creation (when same email is not allowed) | C38: allowaccountssameemail disabled; a user with email X exists | D38: Moodle | E38: Moodle_users | F38: High | G38: Pass | H38: AUTOMATED (moodle_users.feature :: Duplicate email is rejected on user creation) Given a registered user When admin tries to create a user with the same email Then the form shows a duplicate-email error | I38: Error that the email address is already registered; user not created | K38: Yes | L38: moodle_users.feature @U-user-6
A39: CGAP-U-3 | B39: Invalid username (uppercase/spaces) is rejected by the username policy | C39: Username policy (force lowercase / no spaces) enforced | D39: Moodle | E39: Moodle_users | F39: Medium | G39: Pass | H39: 1) Add a new user 2) Enter username with uppercase or spaces (e.g. 'Bad Name') 3) Save | I39: Username validation error is shown; user not created | K39: Yes | L39: moodle_users.feature @U-user-26
A40: CGAP-U-4 | B40: Admin can assign a system role to a user | C40: Admin logged in; target user exists | D40: Moodle | E40: Moodle_users | F40: High | G40: Pass | H40: 1) Site admin > Users > Permissions > Assign system roles 2) Select a role 3) Add the user | I40: User is granted the selected system role | K40: Yes | L40: moodle_users.feature @U-user-30
A41: CGAP-U-5 | B41: Admin can bulk suspend/delete users from the user list | C41: Multiple users exist | D41: Moodle | E41: Moodle_users | F41: High | G41: Pass | H41: 1) Site admin > Users > Bulk user actions 2) Filter and add users to selection 3) Choose Suspend (or Delete) 4) Confirm | I41: The action is applied to every selected user | K41: Yes | L41: moodle_users.feature @U-user-31
A42: CGAP-U-6 | B42: A deleted user cannot log in and is not listed | C42: A test user exists | D42: Moodle | E42: Moodle_users | F42: High | G42: Pass | H42: AUTOMATED (moodle_users.feature :: A deleted user cannot log in and is not listed) Given a registered user When admin deletes the user Then the deleted user cannot log in And the deleted user is not listed | I42: Login fails; the user no longer appears in the user list | K42: Yes | L42: moodle_users.feature @U-user-15
A43: CGAP-U-7 | B43: Force password change on first login is enforced | C43: Admin logged in | D43: Moodle | E43: Moodle_users | F43: Medium | G43: Pass | H43: AUTOMATED (moodle_users.feature :: Force password change on first login is enforced) When admin creates a user with force password change Then the user is forced to change password on login | I43: User is required to change the password before continuing | K43: Yes | L43: moodle_users.feature @U-user-20
A44: CGAP-U-8 | B44: A user can change their own password | C44: A registered user | D44: Moodle | E44: Moodle_users | F44: High | G44: Pass | H44: AUTOMATED (moodle_users.feature :: A user can change their own password) Given a registered user Then the user can change their own password and log in with it | I44: Password is changed; user can log in with the new password | K44: Yes | L44: moodle_users.feature @U-user-21
A45: CGAP-U-9 | B45: Admin can add and remove a user from a cohort | C45: A cohort and a user exist | D45: Moodle | E45: Moodle_users | F45: High | G45: Pass | H45: 1) Site admin > Users > Cohorts > Assign 2) Add the user 3) Then remove the user | I45: Cohort membership updates to reflect add and remove | K45: Yes | L45: moodle_users.feature @U-user-25
